<?xml version="1.0"?>
<robot name="RAPID" xmlns:xacro="http://www.ros.org/wiki/xacro" >

    <!-- UNITS: Metric units for everything. Kilograms for mass and Meters for length -->

    <material name="white">
        <color rgba="1 1 1 1" />
    </material>

    <material name="black">
        <color rgba="0.25 0.25 0.25 1"/>
    </material>

    <material name="red">
        <color rgba="1 0 0 1"/>
    </material>

    <material name="gray">
        <color rgba="0.8 0.8 0.8 1"/>
    </material>

    <material name="gold">
        <color rgba="1 0.84 0 1"/>
    </material>



    <!-- BASE LINK -->

    <link name="base_link">

    </link>

    <!-- BASE_FOOTPRINT LINK -->

    <joint name="base_footprint_joint" type="fixed">
        <parent link="base_link"/>
        <child link="base_footprint"/>
        <origin xyz="0 0 0" rpy="0 0 0"/>
    </joint>

    <link name="base_footprint">
    </link>


    <!-- CHASSIS BASE LINK -->

    <joint name="chassis_base_joint" type="fixed">
        <parent link="base_link"/>
        <child link="chassis_base"/>
        <!-- change this so that the origin is on the complete back wall -->
        <origin xyz="-0.291465 0 -0.026035"/>
    </joint>

    <link name="chassis_base">
        <visual>
            <origin xyz="0.1778 0 0.06985"/>
            <geometry>
                <box size="0.3556 0.2032 0.1397"/>
            </geometry>
            <material name="black"/>
        </visual>
        <collision>
            <origin xyz="0.1778 0 0.06985"/>
            <geometry>
                <box size="0.3556 0.2032 0.1397"/>
            </geometry>
        </collision>
    </link>

    <gazebo reference="chassis_base">
        <material>Gazebo/Black</material>
    </gazebo>

    <!-- CHASSIS TOP LINK -->

    <joint name="chassis_top_joint" type="fixed">
        <origin xyz="0.1778 0 0.1397" rpy="0 0 0" />
        <parent link="chassis_base"/>
        <child link="chassis_top"/>
    </joint>

    <link name="chassis_top">
        <visual>
            <origin xyz="0 0 0.09525"/>
            <geometry>
                <box size="0.4064 0.254 0.1905" />
            </geometry>
            <material name="gold" />
        </visual>
        <collision>
            <origin xyz="0 0 0" rpy="0 0 0" />
            <geometry>
                <box size="0.4064 0.254 0.1905" />
            </geometry>
        </collision>
    </link>

    <gazebo reference="chassis_top">
        <material>Gazebo/Gold</material>
    </gazebo>

    <!-- LID LINK -->

    <joint name="lid_joint" type="fixed">
        <origin xyz="0 0 0.1905" />
        <parent link="chassis_top"/>
        <child link="lid"/>
    </joint>

    <link name="lid">
        <visual>
            <origin xyz="0 0 0.0127" />
            <geometry>
                <box size="0.4064 0.254 0.0254" />
            </geometry>
            <material name="black" />
        </visual>
        <collision>
            <origin xyz="0 0 0.0254" />
            <geometry>
                <box size="0.4064 0.254 0.0254" />
            </geometry>
        </collision>
    </link>

    <gazebo reference="lid">
        <material>Gazebo/Black</material>
    </gazebo>

    <!-- BACK LEFT WHEEL LINK -->

    <joint name="back_left_wheel_joint" type="continuous">
        <parent link="base_link"/>
        <child link="back_left_wheel"/>
        <origin xyz="0 0.1143 0" rpy="-1.5707963267948966 0 0" />
        <axis xyz="0 0 1"/>
    </joint>

    <link name="back_left_wheel">
        <visual>
            <geometry>
                <cylinder radius="0.0762" length="0.0254"/>
            </geometry>
            <material name="gray"/>
        </visual>
        <collision>
            <geometry>
                <sphere radius="0.0762"/>
            </geometry>
        </collision>
    </link>

    <gazebo reference="back_left_wheel">
        <material>Gazebo/Gray</material>
    </gazebo>

    <!-- FRONT LEFT WHEEL LINK -->

    <joint name="front_left_wheel_joint" type="continuous">
        <parent link="base_link"/>
        <child link="front_left_wheel"/>
        <origin xyz="-0.22733 0.1143 0" rpy="-1.5707963267948966 0 0" />
        <axis xyz="0 0 1"/>
    </joint>

    <link name="front_left_wheel">
        <visual>
            <geometry>
                <cylinder radius="0.0762" length="0.0254"/>
            </geometry>
            <material name="gray"/>
        </visual>
        <collision>
            <geometry>
                <sphere radius="0.0762"/>
            </geometry>
        </collision>
    </link>

    <gazebo reference="front_left_wheel">
        <material>Gazebo/Gray</material>
    </gazebo>

    <!-- BACK RIGHT WHEEL LINK -->

    <joint name="back_right_wheel_joint" type="continuous">
        <parent link="base_link"/>
        <child link="back_right_wheel"/>
        <origin xyz="0 -0.1143 0" rpy="1.5707963267948966 0 0" />
        <axis xyz="0 0 -1"/>
    </joint>

    <link name="back_right_wheel">
        <visual>
            <geometry>
                <cylinder radius="0.0762" length="0.0254"/>
            </geometry>
            <material name="gray"/>
        </visual>
        <collision>
            <geometry>
                <sphere radius="0.0762"/>
            </geometry>
        </collision>
    </link>

    <gazebo reference="back_right_wheel">
        <material>Gazebo/Gray</material>
    </gazebo>

    <!-- FRONT RIGHT WHEEL LINK -->

    <joint name="front_right_wheel_joint" type="continuous">
        <parent link="base_link"/>
        <child link="front_right_wheel"/>
        <origin xyz="-0.22733 -0.1143 0" rpy="1.5707963267948966 0 0" />
        <axis xyz="0 0 -1"/>
    </joint>

    <link name="front_right_wheel">
        <visual>
            <geometry>
                <cylinder radius="0.0762" length="0.0254"/>
            </geometry>
            <material name="gray"/>
        </visual>
        <collision>
            <geometry>
                <sphere radius="0.0762"/>
            </geometry>
        </collision>
    </link>

    <gazebo reference="front_right_wheel">
        <material>Gazebo/Gray</material>
    </gazebo>



    <!-- LiDAR -->
    <joint name="laser_joint" type="fixed">
        <parent link="lid"/>
        <child link="laser"/>
        <!-- Change origin in a minute -->
        <origin xyz="-0.09525 0 0.04" rpy="0 0 0"/>
    </joint>

    <link name="laser">
        <visual>
            <geometry>
                <cylinder radius="0.05" length="0.04"/>
            </geometry>
            <material name="red"/>
        </visual>
        <collision>
            <geometry>
                <cylinder radius="0.05" length="0.04"/>
            </geometry>
        </collision>
    </link>

    <gazebo reference="laser">
        <material>Gazebo/Red</material>
 
        <sensor name="laser_sensor" type="ray">
            <pose> 0 0 0 0 0 0 </pose>
            <visualize>false</visualize>
            <update_rate>10</update_rate>
            <ray>
                <scan>
                    <horizontal>
                        <samples>360</samples>
                        <min_angle>-3.14</min_angle>
                        <max_angle>3.14</max_angle>
                    </horizontal>
                </scan>
                <range>
                    <min>0.3</min>
                    <max>12</max>
                </range>
            </ray>
            <plugin name="laser_controller" filename="libgazebo_ros_ray_sensor.so">
                <ros>
                    <!-- Data Published Here to this topic -->
                    <argument>~/out:=scan</argument>
                </ros>
                <output_type>sensor_msgs/LaserScan</output_type>
                <frame_name>laser</frame_name>
            </plugin>
        </sensor>
    </gazebo>



    <!-- Front Camera -->
    <joint name="front_camera_joint" type="fixed">
        <parent link="chassis_base"/>
        <child link="front_camera_link"/>
        <origin xyz="0.361 0.0866 0.06985" rpy="0 0 0"/>
    </joint>

    <link name="front_camera_link">
        <visual>
            <geometry>
                <box size="0.010 0.03 0.03"/>
            </geometry>
            <material name="red"/>
        </visual>
    </link>


    <joint name="front_camera_optical_joint" type="fixed">
        <parent link="front_camera_link"/>
        <child link="front_camera_link_optical"/>
        <origin xyz="0 0 0" rpy="-1.5707963267948966 0 -1.5707963267948966"/>
    </joint>

    <link name="front_camera_link_optical"></link>

    <gazebo reference="front_camera_link">
        <material>Gazebo/Red</material>

        <sensor name="front_camera" type="camera">
            <pose> 0 0 0 0 0 0 </pose>
            <visualize>true</visualize>
            <update_rate>10</update_rate>
            <camera>
                <horizontal_fov>1.089</horizontal_fov>
                <image>
                    <format>R8G8B8</format>
                    <width>640</width>
                    <height>480</height>
                </image>
                <clip>
                    <near>0.05</near>
                    <far>8.0</far>
                </clip>
            </camera>
            <plugin name="front_camera_controller" filename="libgazebo_ros_camera.so">
                <frame_name>front_camera_link_optical</frame_name>
            </plugin>
        </sensor>
    </gazebo>



    <!-- Rear Camera -->
    <joint name="rear_camera_joint" type="fixed">
        <parent link="chassis_base"/>
        <child link="rear_camera_link"/>
        <origin xyz="-0.005 0.0866 0.06985" rpy="0 0 -3.14159265359"/>
    </joint>

    <link name="rear_camera_link">
        <visual>
            <geometry>
                <box size="0.010 0.03 0.03"/>
            </geometry>
            <material name="red"/>
        </visual>
    </link>


    <joint name="rear_camera_optical_joint" type="fixed">
        <parent link="rear_camera_link"/>
        <child link="rear_camera_link_optical"/>
        <origin xyz="0 0 0" rpy="-1.5707963267948966 0 -1.5707963267948966"/>
    </joint>

    <link name="rear_camera_link_optical"></link>

    <gazebo reference="rear_camera_link">
        <material>Gazebo/Red</material>

        <sensor name="rear_camera" type="camera">
            <pose> 0 0 0 0 0 0 </pose>
            <visualize>true</visualize>
            <update_rate>10</update_rate>
            <camera>
                <horizontal_fov>1.089</horizontal_fov>
                <image>
                    <format>R8G8B8</format>
                    <width>640</width>
                    <height>480</height>
                </image>
                <clip>
                    <near>0.05</near>
                    <far>8.0</far>
                </clip>
            </camera>
            <plugin name="rear_camera_controller" filename="libgazebo_ros_camera.so">
                <frame_name>rear_camera_link_optical</frame_name>
            </plugin>
        </sensor>
    </gazebo>
 
</robot>